Workbook

Sheet Summary
A1: UAV-X v3.1 - summary of the 60 simulations (all values are live formulas)
A2: Default planner adaptive-spare · E1 (critical fault on the busiest relay) · 30 dev + 30 held-out saved scenarios
A4: Metric | B4: Column | C4: All 60: mean | D4: All 60: median | E4: All 60: best | F4: All 60: worst | G4: Dev: mean | H4: Held-out: mean | I4: Runs with value
A5: Imagery complete (s) | B5: F | C5: =AVERAGE('All 60 Runs'!F4:F63) -> 559.86 | D5: =MEDIAN('All 60 Runs'!F4:F63) -> 542.75 | E5: =MIN('All 60 Runs'!F4:F63) -> 300.2 | F5: =MAX('All 60 Runs'!F4:F63) -> 871.5 | G5: =AVERAGEIFS('All 60 Runs'!F4:F63,'All 60 Runs'!B4:B63,"dev") -> 521.57333 | H5: =AVERAGEIFS('All 60 Runs'!F4:F63,'All 60 Runs'!B4:B63,"held-out") -> 598.14667 | I5: =COUNT('All 60 Runs'!F4:F63) -> 60
A6: Fleet landed (s) | B6: G | C6: =AVERAGE('All 60 Runs'!G4:G63) -> 680.47167 | D6: =MEDIAN('All 60 Runs'!G4:G63) -> 670.4 | E6: =MIN('All 60 Runs'!G4:G63) -> 371.1 | F6: =MAX('All 60 Runs'!G4:G63) -> 1007 | G6: =AVERAGEIFS('All 60 Runs'!G4:G63,'All 60 Runs'!B4:B63,"dev") -> 639.69667 | H6: =AVERAGEIFS('All 60 Runs'!G4:G63,'All 60 Runs'!B4:B63,"held-out") -> 721.24667 | I6: =COUNT('All 60 Runs'!G4:G63) -> 60
A7: High-priority response (s) | B7: H | C7: =AVERAGE('All 60 Runs'!H4:H63) -> 87.451667 | D7: =MEDIAN('All 60 Runs'!H4:H63) -> 83.3 | E7: =MIN('All 60 Runs'!H4:H63) -> 23.3 | F7: =MAX('All 60 Runs'!H4:H63) -> 217.7 | G7: =AVERAGEIFS('All 60 Runs'!H4:H63,'All 60 Runs'!B4:B63,"dev") -> 77.35 | H7: =AVERAGEIFS('All 60 Runs'!H4:H63,'All 60 Runs'!B4:B63,"held-out") -> 97.553333 | I7: =COUNT('All 60 Runs'!H4:H63) -> 60
A8: Sites within 60 s (fraction) | B8: I | C8: =AVERAGE('All 60 Runs'!I4:I63) -> 0.97708333 | D8: =MEDIAN('All 60 Runs'!I4:I63) -> 1 | E8: =MAX('All 60 Runs'!I4:I63) -> 1 | F8: =MIN('All 60 Runs'!I4:I63) -> 0.875 | G8: =AVERAGEIFS('All 60 Runs'!I4:I63,'All 60 Runs'!B4:B63,"dev") -> 0.97916667 | H8: =AVERAGEIFS('All 60 Runs'!I4:I63,'All 60 Runs'!B4:B63,"held-out") -> 0.975 | I8: =COUNT('All 60 Runs'!I4:I63) -> 60
A9: Connectivity (%) | B9: J | C9: =AVERAGE('All 60 Runs'!J4:J63) -> 93.531667 | D9: =MEDIAN('All 60 Runs'!J4:J63) -> 93.5 | E9: =MAX('All 60 Runs'!J4:J63) -> 99.1 | F9: =MIN('All 60 Runs'!J4:J63) -> 74.9 | G9: =AVERAGEIFS('All 60 Runs'!J4:J63,'All 60 Runs'!B4:B63,"dev") -> 94.2 | H9: =AVERAGEIFS('All 60 Runs'!J4:J63,'All 60 Runs'!B4:B63,"held-out") -> 92.863333 | I9: =COUNT('All 60 Runs'!J4:J63) -> 60
A10: Time partitioned (%) | B10: K | C10: =AVERAGE('All 60 Runs'!K4:K63) -> 19.691667 | D10: =MEDIAN('All 60 Runs'!K4:K63) -> 20 | E10: =MIN('All 60 Runs'!K4:K63) -> 3.6 | F10: =MAX('All 60 Runs'!K4:K63) -> 45.4 | G10: =AVERAGEIFS('All 60 Runs'!K4:K63,'All 60 Runs'!B4:B63,"dev") -> 18.01 | H10: =AVERAGEIFS('All 60 Runs'!K4:K63,'All 60 Runs'!B4:B63,"held-out") -> 21.373333 | I10: =COUNT('All 60 Runs'!K4:K63) -> 60
A11: Time with a critical relay (%) | B11: L | C11: =AVERAGE('All 60 Runs'!L4:L63) -> 55.838333 | D11: =MEDIAN('All 60 Runs'!L4:L63) -> 57 | E11: =MIN('All 60 Runs'!L4:L63) -> 18.3 | F11: =MAX('All 60 Runs'!L4:L63) -> 76.9 | G11: =AVERAGEIFS('All 60 Runs'!L4:L63,'All 60 Runs'!B4:B63,"dev") -> 55.666667 | H11: =AVERAGEIFS('All 60 Runs'!L4:L63,'All 60 Runs'!B4:B63,"held-out") -> 56.01 | I11: =COUNT('All 60 Runs'!L4:L63) -> 60
A12: Time redundant (%) | B12: M | C12: =AVERAGE('All 60 Runs'!M4:M63) -> 24.481667 | D12: =MEDIAN('All 60 Runs'!M4:M63) -> 22.3 | E12: =MAX('All 60 Runs'!M4:M63) -> 49.4 | F12: =MIN('All 60 Runs'!M4:M63) -> 13.4 | G12: =AVERAGEIFS('All 60 Runs'!M4:M63,'All 60 Runs'!B4:B63,"dev") -> 26.33 | H12: =AVERAGEIFS('All 60 Runs'!M4:M63,'All 60 Runs'!B4:B63,"held-out") -> 22.633333 | I12: =COUNT('All 60 Runs'!M4:M63) -> 60
A13: Disconnected UAV-s | B13: N | C13: =AVERAGE('All 60 Runs'!N4:N63) -> 163.79 | D13: =MEDIAN('All 60 Runs'!N4:N63) -> 155.25 | E13: =MIN('All 60 Runs'!N4:N63) -> 12.4 | F13: =MAX('All 60 Runs'!N4:N63) -> 707.6 | G13: =AVERAGEIFS('All 60 Runs'!N4:N63,'All 60 Runs'!B4:B63,"dev") -> 139.84333 | H13: =AVERAGEIFS('All 60 Runs'!N4:N63,'All 60 Runs'!B4:B63,"held-out") -> 187.73667 | I13: =COUNT('All 60 Runs'!N4:N63) -> 60
A14: Heartbeat PDR (%) | B14: O | C14: =AVERAGE('All 60 Runs'!O4:O63) -> 94.303333 | D14: =MEDIAN('All 60 Runs'!O4:O63) -> 94.3 | E14: =MAX('All 60 Runs'!O4:O63) -> 99.4 | F14: =MIN('All 60 Runs'!O4:O63) -> 79.9 | G14: =AVERAGEIFS('All 60 Runs'!O4:O63,'All 60 Runs'!B4:B63,"dev") -> 94.693333 | H14: =AVERAGEIFS('All 60 Runs'!O4:O63,'All 60 Runs'!B4:B63,"held-out") -> 93.913333 | I14: =COUNT('All 60 Runs'!O4:O63) -> 60
A15: Command ack p95 (s) | B15: P | C15: =AVERAGE('All 60 Runs'!P4:P63) -> 0.61586667 | D15: =MEDIAN('All 60 Runs'!P4:P63) -> 0.616 | E15: =MIN('All 60 Runs'!P4:P63) -> 0.58 | F15: =MAX('All 60 Runs'!P4:P63) -> 0.703 | G15: =AVERAGEIFS('All 60 Runs'!P4:P63,'All 60 Runs'!B4:B63,"dev") -> 0.62 | H15: =AVERAGEIFS('All 60 Runs'!P4:P63,'All 60 Runs'!B4:B63,"held-out") -> 0.61173333 | I15: =COUNT('All 60 Runs'!P4:P63) -> 60
A16: UAVs orphaned by fault | B16: Q | C16: =AVERAGE('All 60 Runs'!Q4:Q63) -> 1.0666667 | D16: =MEDIAN('All 60 Runs'!Q4:Q63) -> 0 | E16: =MIN('All 60 Runs'!Q4:Q63) -> 0 | F16: =MAX('All 60 Runs'!Q4:Q63) -> 4 | G16: =AVERAGEIFS('All 60 Runs'!Q4:Q63,'All 60 Runs'!B4:B63,"dev") -> 1.2333333 | H16: =AVERAGEIFS('All 60 Runs'!Q4:Q63,'All 60 Runs'!B4:B63,"held-out") -> 0.9 | I16: =COUNT('All 60 Runs'!Q4:Q63) -> 60
A17: Stable recovery confirmed (s) | B17: R | C17: =AVERAGE('All 60 Runs'!R4:R63) -> 22.498824 | D17: =MEDIAN('All 60 Runs'!R4:R63) -> 21.57 | E17: =MIN('All 60 Runs'!R4:R63) -> 10.75 | F17: =MAX('All 60 Runs'!R4:R63) -> 37.06 | G17: =AVERAGEIFS('All 60 Runs'!R4:R63,'All 60 Runs'!B4:B63,"dev") -> 23.149 | H17: =AVERAGEIFS('All 60 Runs'!R4:R63,'All 60 Runs'!B4:B63,"held-out") -> 21.57 | I17: =COUNT('All 60 Runs'!R4:R63) -> 17
A18: Fault UAV-s disconnected | B18: S | C18: =AVERAGE('All 60 Runs'!S4:S63) -> 18.275 | D18: =MEDIAN('All 60 Runs'!S4:S63) -> 0 | E18: =MIN('All 60 Runs'!S4:S63) -> 0 | F18: =MAX('All 60 Runs'!S4:S63) -> 127.7 | G18: =AVERAGEIFS('All 60 Runs'!S4:S63,'All 60 Runs'!B4:B63,"dev") -> 22.296667 | H18: =AVERAGEIFS('All 60 Runs'!S4:S63,'All 60 Runs'!B4:B63,"held-out") -> 14.253333 | I18: =COUNT('All 60 Runs'!S4:S63) -> 60
A19: Min separation (m) | B19: U | C19: =AVERAGE('All 60 Runs'!U4:U63) -> 6.0391667 | D19: =MEDIAN('All 60 Runs'!U4:U63) -> 6 | E19: =MAX('All 60 Runs'!U4:U63) -> 8.03 | F19: =MIN('All 60 Runs'!U4:U63) -> 6 | G19: =AVERAGEIFS('All 60 Runs'!U4:U63,'All 60 Runs'!B4:B63,"dev") -> 6.0683333 | H19: =AVERAGEIFS('All 60 Runs'!U4:U63,'All 60 Runs'!B4:B63,"held-out") -> 6.01 | I19: =COUNT('All 60 Runs'!U4:U63) -> 60
A20: Min landing battery (%) | B20: Y | C20: =AVERAGE('All 60 Runs'!Y4:Y63) -> 28.908333 | D20: =MEDIAN('All 60 Runs'!Y4:Y63) -> 26.7 | E20: =MAX('All 60 Runs'!Y4:Y63) -> 63.6 | F20: =MIN('All 60 Runs'!Y4:Y63) -> 20.1 | G20: =AVERAGEIFS('All 60 Runs'!Y4:Y63,'All 60 Runs'!B4:B63,"dev") -> 30.08 | H20: =AVERAGEIFS('All 60 Runs'!Y4:Y63,'All 60 Runs'!B4:B63,"held-out") -> 27.736667 | I20: =COUNT('All 60 Runs'!Y4:Y63) -> 60
A22: Pass counts (formulas over the check columns)
A23: Check | B23: Column | C23: All 60 | D23: Dev (of 30) | E23: Held-out (of 30)
A24: Imagery complete within limit | B24: Z | C24: =COUNTIF('All 60 Runs'!Z4:Z63,"PASS") -> 60 | D24: =COUNTIFS('All 60 Runs'!Z4:Z63,"PASS",'All 60 Runs'!B4:B63,"dev") -> 30 | E24: =COUNTIFS('All 60 Runs'!Z4:Z63,"PASS",'All 60 Runs'!B4:B63,"held-out") -> 30
A25: High-priority response within limit | B25: AA | C25: =COUNTIF('All 60 Runs'!AA4:AA63,"PASS") -> 60 | D25: =COUNTIFS('All 60 Runs'!AA4:AA63,"PASS",'All 60 Runs'!B4:B63,"dev") -> 30 | E25: =COUNTIFS('All 60 Runs'!AA4:AA63,"PASS",'All 60 Runs'!B4:B63,"held-out") -> 30
A26: Timely sites >= minimum | B26: AB | C26: =COUNTIF('All 60 Runs'!AB4:AB63,"PASS") -> 60 | D26: =COUNTIFS('All 60 Runs'!AB4:AB63,"PASS",'All 60 Runs'!B4:B63,"dev") -> 30 | E26: =COUNTIFS('All 60 Runs'!AB4:AB63,"PASS",'All 60 Runs'!B4:B63,"held-out") -> 30
A27: Separation >= 5 m, no near miss | B27: AC | C27: =COUNTIF('All 60 Runs'!AC4:AC63,"PASS") -> 60 | D27: =COUNTIFS('All 60 Runs'!AC4:AC63,"PASS",'All 60 Runs'!B4:B63,"dev") -> 30 | E27: =COUNTIFS('All 60 Runs'!AC4:AC63,"PASS",'All 60 Runs'!B4:B63,"held-out") -> 30
A28: Landing battery >= reserve | B28: AD | C28: =COUNTIF('All 60 Runs'!AD4:AD63,"PASS") -> 60 | D28: =COUNTIFS('All 60 Runs'!AD4:AD63,"PASS",'All 60 Runs'!B4:B63,"dev") -> 30 | E28: =COUNTIFS('All 60 Runs'!AD4:AD63,"PASS",'All 60 Runs'!B4:B63,"held-out") -> 30
A29: No collision / depletion; fleet landed in time | B29: AE | C29: =COUNTIF('All 60 Runs'!AE4:AE63,"PASS") -> 60 | D29: =COUNTIFS('All 60 Runs'!AE4:AE63,"PASS",'All 60 Runs'!B4:B63,"dev") -> 30 | E29: =COUNTIFS('All 60 Runs'!AE4:AE63,"PASS",'All 60 Runs'!B4:B63,"held-out") -> 30
A30: ALL CHECKS (operational success) | B30: AF | C30: =COUNTIF('All 60 Runs'!AF4:AF63,"PASS") -> 60 | D30: =COUNTIFS('All 60 Runs'!AF4:AF63,"PASS",'All 60 Runs'!B4:B63,"dev") -> 30 | E30: =COUNTIFS('All 60 Runs'!AF4:AF63,"PASS",'All 60 Runs'!B4:B63,"held-out") -> 30
A32: Total near misses (< 5 m) | B32: V | C32: =SUM('All 60 Runs'!V4:V63) -> 0
A33: Total collisions (< 1.5 m proxy) | B33: W | C33: =SUM('All 60 Runs'!W4:W63) -> 0
A34: Total battery depletions | B34: X | C34: =SUM('All 60 Runs'!X4:X63) -> 0
A35: Total energy handovers | B35: T | C35: =SUM('All 60 Runs'!T4:T63) -> 28
A37: Best/worst: for 'lower is better' metrics best = MIN, worst = MAX, and the reverse for 'higher is better'. Blank cells (e.g. no orphaned UAVs, so no recovery to time) are ignored by AVERAGE/MEDIAN; 'Runs with value' shows the count.

Sheet Constraints
A1: Predeclared INTERNAL constraints (config.CONSTRAINTS, fixed 2026-09-25)
A3: Constraint | B3: Threshold | C3: Unit | D3: Meaning
A4: Imagery complete by | B4: 900 | C4: s | D4: All site imagery must reach the GCS by this time
A5: Fleet landed by | B5: 1200 | C5: s | D5: Every surviving UAV on its pad (observer)
A6: High-priority response | B6: 240 | C6: s | D6: New high-priority report -> its imagery at GCS
A7: Timely sites, minimum fraction | B7: 0.75 | C7: fraction | D7: Sites whose imagery arrives <= 60 s after survey
A8: Minimum separation | B8: 5 | C8: m | D8: No controller-caused separation below this
A9: Collision proxy | B9: 1.5 | C9: m | D9: Geometric contact proxy; must never occur
A10: Minimum landing battery | B10: 15 | C10: % | D10: The energy reserve
A12: Blue text on yellow = inputs. Changing a threshold here re-evaluates every check column on the 'All 60 Runs' sheet and the pass counts on 'Summary'. Source: user-approved internal test thresholds (UAV-X publishes none for Stage 1).

Sheet All 60 Runs
A1: UAV-X v3.1 - all 60 simulations (E1: critical fault on the busiest relay, default planner adaptive-spare, 30 dev + 30 held-out scenarios)
Z2: Live formula checks ->
A3: # | B3: Set | C3: Scenario | D3: Fault | E3: Faulted UAV | F3: Imagery complete (s) | G3: Fleet landed (s) | H3: High-priority response (s) | I3: Sites within 60 s (fraction) | J3: Connectivity (%) | K3: Partitioned (%) | L3: Critical relay (%) | M3: Redundant (%) | N3: Disconnected UAV-s | O3: Heartbeat PDR (%) | P3: Command ack p95 (s) | Q3: UAVs orphaned by fault | R3: Stable recovery confirmed (s) | S3: Fault UAV-s disconnected | T3: Handovers | U3: Min separation (m) | V3: Near misses | W3: Collisions | X3: Depletions | Y3: Min landing battery (%) | Z3: CHECK imagery <= limit | AA3: CHECK HP <= limit | AB3: CHECK timely >= min | AC3: CHECK separation | AD3: CHECK landing >= reserve | AE3: CHECK no collision / depletion | AF3: ALL CHECKS (formula) | AG3: Simulator verdict
A4: 1 | B4: dev | C4: seed_000 | D4: failsafe-busiest | E4: 1 | F4: 452.8 | G4: 581.3 | H4: 42.6 | I4: 0.875 | J4: 92.6 | K4: 16.8 | L4: 54.3 | M4: 28.9 | N4: 157.6 | O4: 94.1 | P4: 0.646 | Q4: 0 | S4: 0 | T4: 0 | U4: 6 | V4: 0 | W4: 0 | X4: 0 | Y4: 20.8 | Z4: =IF(F4<=Constraints!$B$4,"PASS","FAIL") -> PASS | AA4: =IF(H4="","PASS",IF(H4<=Constraints!$B$6,"PASS","FAIL")) -> PASS | AB4: =IF(I4>=Constraints!$B$7,"PASS","FAIL") -> PASS | AC4: =IF(AND(U4>=Constraints!$B$8,V4=0),"PASS","FAIL") -> PASS | AD4: =IF(Y4>=Constraints!$B$10-0.000001,"PASS","FAIL") -> PASS | AE4: =IF(AND(W4=0,X4=0,G4<=Constraints!$B$5),"PASS","FAIL") -> PASS | AF4: =IF(COUNTIF(Z4:AE4,"FAIL")=0,"PASS","FAIL") -> PASS | AG4: PASS
A5: 2 | B5: dev | C5: seed_001 | D5: hard-busiest | E5: 2 | F5: 675.6 | G5: 779.8 | H5: 68.2 | I5: 1 | J5: 92.3 | K5: 21.2 | L5: 60.6 | M5: 18.2 | N5: 218.9 | O5: 93.1 | P5: 0.602 | Q5: 4 | R5: 27.2 | S5: 88.3 | T5: 1 | U5: 6 | V5: 0 | W5: 0 | X5: 0 | Y5: 25.3 | Z5: =IF(F5<=Constraints!$B$4,"PASS","FAIL") -> PASS | AA5: =IF(H5="","PASS",IF(H5<=Constraints!$B$6,"PASS","FAIL")) -> PASS | AB5: =IF(I5>=Constraints!$B$7,"PASS","FAIL") -> PASS | AC5: =IF(AND(U5>=Constraints!$B$8,V5=0),"PASS","FAIL") -> PASS | AD5: =IF(Y5>=Constraints!$B$10-0.000001,"PASS","FAIL") -> PASS | AE5: =IF(AND(W5=0,X5=0,G5<=Constraints!$B$5),"PASS","FAIL") -> PASS | AF5: =IF(COUNTIF(Z5:AE5,"FAIL")=0,"PASS","FAIL") -> PASS | AG5: PASS
A6: 3 | B6: dev | C6: seed_002 | D6: failsafe-busiest | E6: 3 | F6: 351.2 | G6: 481.7 | H6: 43.8 | I6: 0.875 | J6: 94.3 | K6: 13.5 | L6: 50.6 | M6: 35.9 | N6: 106.7 | O6: 95.4 | P6: 0.649 | Q6: 0 | S6: 0 | T6: 0 | U6: 6 | V6: 0 | W6: 0 | X6: 0 | Y6: 33 | Z6: =IF(F6<=Constraints!$B$4,"PASS","FAIL") -> PASS | AA6: =IF(H6="","PASS",IF(H6<=Constraints!$B$6,"PASS","FAIL")) -> PASS | AB6: =IF(I6>=Constraints!$B$7,"PASS","FAIL") -> PASS | AC6: =IF(AND(U6>=Constraints!$B$8,V6=0),"PASS","FAIL") -> PASS | AD6: =IF(Y6>=Constraints!$B$10-0.000001,"PASS","FAIL") -> PASS | AE6: =IF(AND(W6=0,X6=0,G6<=Constraints!$B$5),"PASS","FAIL") -> PASS | AF6: =IF(COUNTIF(Z6:AE6,"FAIL")=0,"PASS","FAIL") -> PASS | AG6: PASS
A7: 4 | B7: dev | C7: seed_003 | D7: hard-busiest | E7: 1 | F7: 532.9 | G7: 633.7 | H7: 108.1 | I7: 1 | J7: 94.4 | K7: 19.4 | L7: 50.7 | M7: 29.9 | N7: 112.3 | O7: 95 | P7: 0.596 | Q7: 0 | S7: 0 | T7: 1 | U7: 6 | V7: 0 | W7: 0 | X7: 0 | Y7: 25.5 | Z7: =IF(F7<=Constraints!$B$4,"PASS","FAIL") -> PASS | AA7: =IF(H7="","PASS",IF(H7<=Constraints!$B$6,"PASS","FAIL")) -> PASS | AB7: =IF(I7>=Constraints!$B$7,"PASS","FAIL") -> PASS | AC7: =IF(AND(U7>=Constraints!$B$8,V7=0),"PASS","FAIL") -> PASS | AD7: =IF(Y7>=Constraints!$B$10-0.000001,"PASS","FAIL") -> PASS | AE7: =IF(AND(W7=0,X7=0,G7<=Constraints!$B$5),"PASS","FAIL") -> PASS | AF7: =IF(COUNTIF(Z7:AE7,"FAIL")=0,"PASS","FAIL") -> PASS | AG7: PASS
A8: 5 | B8: dev | C8: seed_004 | D8: hard-busiest | E8: 4 | F8: 502.1 | G8: 654 | H8: 47.8 | I8: 1 | J8: 96 | K8: 11.4 | L8: 66.2 | M8: 22.4 | N8: 95.9 | O8: 95.8 | P8: 0.634 | Q8: 4 | R8: 14.53 | S8: 37.9 | T8: 0 | U8: 6 | V8: 0 | W8: 0 | X8: 0 | Y8: 33.9 | Z8: =IF(F8<=Constraints!$B$4,"PASS","FAIL") -> PASS | AA8: =IF(H8="","PASS",IF(H8<=Constraints!$B$6,"PASS","FAIL")) -> PASS | AB8: =IF(I8>=Constraints!$B$7,"PASS","FAIL") -> PASS | AC8: =IF(AND(U8>=Constraints!$B$8,V8=0),"PASS","FAIL") -> PASS | AD8: =IF(Y8>=Constraints!$B$10-0.000001,"PASS","FAIL") -> PASS | AE8: =IF(AND(W8=0,X8=0,G8<=Constraints!$B$5),"PASS","FAIL") -> PASS | AF8: =IF(COUNTIF(Z8:AE8,"FAIL")=0,"PASS","FAIL") -> PASS | AG8: PASS
A9: 6 | B9: dev | C9: seed_005 | D9: failsafe-busiest | E9: 2 | F9: 566.5 | G9: 661.4 | H9: 92 | I9: 0.875 | J9: 92 | K9: 28.8 | L9: 50.5 | M9: 20.8 | N9: 172.9 | O9: 93.7 | P9: 0.642 | Q9: 0 | S9: 0 | T9: 1 | U9: 6 | V9: 0 | W9: 0 | X9: 0 | Y9: 25.8 | Z9: =IF(F9<=Constraints!$B$4,"PASS","FAIL") -> PASS | AA9: =IF(H9="","PASS",IF(H9<=Constraints!$B$6,"PASS","FAIL")) -> PASS | AB9: =IF(I9>=Constraints!$B$7,"PASS","FAIL") -> PASS | AC9: =IF(AND(U9>=Constraints!$B$8,V9=0),"PASS","FAIL") -> PASS | AD9: =IF(Y9>=Constraints!$B$10-0.000001,"PASS","FAIL") -> PASS | AE9: =IF(AND(W9=0,X9=0,G9<=Constraints!$B$5),"PASS","FAIL") -> PASS | AF9: =IF(COUNTIF(Z9:AE9,"FAIL")=0,"PASS","FAIL") -> PASS | AG9: PASS
A10: 7 | B10: dev | C10: seed_006 | D10: hard-busiest | E10: 5 | F10: 476.4 | G10: 605.2 | H10: 93.1 | I10: 1 | J10: 94.3 | K10: 20.4 | L10: 56.9 | M10: 22.7 | N10: 147.6 | O10: 93.3 | P10: 0.644 | Q10: 3 | R10: 13.12 | S10: 24.2 | T10: 0 | U10: 6.01 | V10: 0 | W10: 0 | X10: 0 | Y10: 32.7 | Z10: =IF(F10<=Constraints!$B$4,"PASS","FAIL") -> PASS | AA10: =IF(H10="","PASS",IF(H10<=Constraints!$B$6,"PASS","FAIL")) -> PASS | AB10: =IF(I10>=Constraints!$B$7,"PASS","FAIL") -> PASS | AC10: =IF(AND(U10>=Constraints!$B$8,V10=0),"PASS","FAIL") -> PASS | AD10: =IF(Y10>=Constraints!$B$10-0.000001,"PASS","FAIL") -> PASS | AE10: =IF(AND(W10=0,X10=0,G10<=Constraints!$B$5),"PASS","FAIL") -> PASS | AF10: =IF(COUNTIF(Z10:AE10,"FAIL")=0,"PASS","FAIL") -> PASS | AG10: PASS
A11: 8 | B11: dev | C11: seed_007 | D11: hard-busiest | E11: 3 | F11: 514.1 | G11: 660.4 | H11: 24 | I11: 0.875 | J11: 92.1 | K11: 18.4 | L11: 59.9 | M11: 21.7 | N11: 203.5 | O11: 92 | P11: 0.632 | Q11: 2 | R11: 27.65 | S11: 45.1 | T11: 0 | U11: 6 | V11: 0 | W11: 0 | X11: 0 | Y11: 32.4 | Z11: =IF(F11<=Constraints!$B$4,"PASS","FAIL") -> PASS | AA11: =IF(H11="","PASS",IF(H11<=Constraints!$B$6,"PASS","FAIL")) -> PASS | AB11: =IF(I11>=Constraints!$B$7,"PASS","FAIL") -> PASS | AC11: =IF(AND(U11>=Constraints!$B$8,V11=0),"PASS","FAIL") -> PASS | AD11: =IF(Y11>=Constraints!$B$10-0.000001,"PASS","FAIL") -> PASS | AE11: =IF(AND(W11=0,X11=0,G11<=Constraints!$B$5),"PASS","FAIL") -> PASS | AF11: =IF(COUNTIF(Z11:AE11,"FAIL")=0,"PASS","FAIL") -> PASS | AG11: PASS
A12: 9 | B12: dev | C12: seed_008 | D12: hard-busiest | E12: 1 | F12: 638 | G12: 738.8 | H12: 45 | I12: 1 | J12: 90 | K12: 35.8 | L12: 37.7 | M12: 26.6 | N12: 259.8 | O12: 91 | P12: 0.599 | Q12: 0 | S12: 0 | T12: 1 | U12: 6 | V12: 0 | W12: 0 | X12: 0 | Y12: 25.2 | Z12: =IF(F12<=Constraints!$B$4,"PASS","FAIL") -> PASS | AA12: =IF(H12="","PASS",IF(H12<=Constraints!$B$6,"PASS","FAIL")) -> PASS | AB12: =IF(I12>=Constraints!$B$7,"PASS","FAIL") -> PASS | AC12: =IF(AND(U12>=Constraints!$B$8,V12=0),"PASS","FAIL") -> PASS | AD12: =IF(Y12>=Constraints!$B$10-0.000001,"PASS","FAIL") -> PASS | AE12: =IF(AND(W12=0,X12=0,G12<=Constraints!$B$5),"PASS","FAIL") -> PASS | AF12: =IF(COUNTIF(Z12:AE12,"FAIL")=0,"PASS","FAIL") -> PASS | AG12: PASS
A13: 10 | B13: dev | C13: seed_009 | D13: hard-busiest | E13: 3 | F13: 546.9 | G13: 677.6 | H13: 102.2 | I13: 1 | J13: 94 | K13: 13.4 | L13: 65.6 | M13: 21 | N13: 152.9 | O13: 94.1 | P13: 0.619 | Q13: 4 | R13: 28.54 | S13: 93.7 | T13: 0 | U13: 6 | V13: 0 | W13: 0 | X13: 0 | Y13: 31.3 | Z13: =IF(F13<=Constraints!$B$4,"PASS","FAIL") -> PASS | AA13: =IF(H13="","PASS",IF(H13<=Constraints!$B$6,"PASS","FAIL")) -> PASS | AB13: =IF(I13>=Constraints!$B$7,"PASS","FAIL") -> PASS | AC13: =IF(AND(U13>=Constraints!$B$8,V13=0),"PASS","FAIL") -> PASS | AD13: =IF(Y13>=Constraints!$B$10-0.000001,"PASS","FAIL") -> PASS | AE13: =IF(AND(W13=0,X13=0,G13<=Constraints!$B$5),"PASS","FAIL") -> PASS | AF13: =IF(COUNTIF(Z13:AE13,"FAIL")=0,"PASS","FAIL") -> PASS | AG13: PASS
A14: 11 | B14: dev | C14: seed_010 | D14: failsafe-busiest | E14: 5 | F14: 633.8 | G14: 730.2 | H14: 102.2 | I14: 1 | J14: 91.3 | K14: 26 | L14: 59.1 | M14: 14.9 | N14: 248.2 | O14: 92.3 | P14: 0.608 | Q14: 0 | S14: 0 | T14: 1 | U14: 8.03 | V14: 0 | W14: 0 | X14: 0 | Y14: 21.9 | Z14: =IF(F14<=Constraints!$B$4,"PASS","FAIL") -> PASS | AA14: =IF(H14="","PASS",IF(H14<=Constraints!$B$6,"PASS","FAIL")) -> PASS | AB14: =IF(I14>=Constraints!$B$7,"PASS","FAIL") -> PASS | AC14: =IF(AND(U14>=Constraints!$B$8,V14=0),"PASS","FAIL") -> PASS | AD14: =IF(Y14>=Constraints!$B$10-0.000001,"PASS","FAIL") -> PASS | AE14: =IF(AND(W14=0,X14=0,G14<=Constraints!$B$5),"PASS","FAIL") -> PASS | AF14: =IF(COUNTIF(Z14:AE14,"FAIL")=0,"PASS","FAIL") -> PASS | AG14: PASS
A15: 12 | B15: dev | C15: seed_011 | D15: failsafe-busiest | E15: 2 | F15: 300.2 | G15: 371.1 | H15: 71.8 | I15: 1 | J15: 99 | K15: 4 | L15: 46.6 | M15: 49.4 | N15: 12.4 | O15: 99.4 | P15: 0.635 | Q15: 0 | S15: 0 | T15: 0 | U15: 6 | V15: 0 | W15: 0 | X15: 0 | Y15: 40.6 | Z15: =IF(F15<=Constraints!$B$4,"PASS","FAIL") -> PASS | AA15: =IF(H15="","PASS",IF(H15<=Constraints!$B$6,"PASS","FAIL")) -> PASS | AB15: =IF(I15>=Constraints!$B$7,"PASS","FAIL") -> PASS | AC15: =IF(AND(U15>=Constraints!$B$8,V15=0),"PASS","FAIL") -> PASS | AD15: =IF(Y15>=Constraints!$B$10-0.000001,"PASS","FAIL") -> PASS | AE15: =IF(AND(W15=0,X15=0,G15<=Constraints!$B$5),"PASS","FAIL") -> PASS | AF15: =IF(COUNTIF(Z15:AE15,"FAIL")=0,"PASS","FAIL") -> PASS | AG15: PASS
A16: 13 | B16: dev | C16: seed_012 | D16: hard-busiest | E16: 2 | F16: 453.6 | G16: 563.5 | H16: 55.1 | I16: 0.875 | J16: 91.2 | K16: 28.2 | L16: 40.4 | M16: 31.3 | N16: 204 | O16: 91.1 | P16: 0.615 | Q16: 4 | R16: 20.16 | S16: 60.4 | T16: 0 | U16: 6 | V16: 0 | W16: 0 | X16: 0 | Y16: 26.1 | Z16: =IF(F16<=Constraints!$B$4,"PASS","FAIL") -> PASS | AA16: =IF(H16="","PASS",IF(H16<=Constraints!$B$6,"PASS","FAIL")) -> PASS | AB16: =IF(I16>=Constraints!$B$7,"PASS","FAIL") -> PASS | AC16: =IF(AND(U16>=Constraints!$B$8,V16=0),"PASS","FAIL") -> PASS | AD16: =IF(Y16>=Constraints!$B$10-0.000001,"PASS","FAIL") -> PASS | AE16: =IF(AND(W16=0,X16=0,G16<=Constraints!$B$5),"PASS","FAIL") -> PASS | AF16: =IF(COUNTIF(Z16:AE16,"FAIL")=0,"PASS","FAIL") -> PASS | AG16: PASS
A17: 14 | B17: dev | C17: seed_013 | D17: failsafe-busiest | E17: 1 | F17: 463.2 | G17: 614.1 | H17: 50.5 | I17: 1 | J17: 99.1 | K17: 3.6 | L17: 68.7 | M17: 27.7 | N17: 19.7 | O17: 99.2 | P17: 0.599 | Q17: 0 | S17: 0 | T17: 0 | U17: 6 | V17: 0 | W17: 0 | X17: 0 | Y17: 34.3 | Z17: =IF(F17<=Constraints!$B$4,"PASS","FAIL") -> PASS | AA17: =IF(H17="","PASS",IF(H17<=Constraints!$B$6,"PASS","FAIL")) -> PASS | AB17: =IF(I17>=Constraints!$B$7,"PASS","FAIL") -> PASS | AC17: =IF(AND(U17>=Constraints!$B$8,V17=0),"PASS","FAIL") -> PASS | AD17: =IF(Y17>=Constraints!$B$10-0.000001,"PASS","FAIL") -> PASS | AE17: =IF(AND(W17=0,X17=0,G17<=Constraints!$B$5),"PASS","FAIL") -> PASS | AF17: =IF(COUNTIF(Z17:AE17,"FAIL")=0,"PASS","FAIL") -> PASS | AG17: PASS
A18: 15 | B18: dev | C18: seed_014 | D18: failsafe-busiest | E18: 2 | F18: 410.5 | G18: 558.3 | H18: 45.8 | I18: 1 | J18: 96.7 | K18: 13 | L18: 57.8 | M18: 29.2 | N18: 72.6 | O18: 97.3 | P18: 0.634 | Q18: 0 | S18: 0 | T18: 0 | U18: 6 | V18: 0 | W18: 0 | X18: 0 | Y18: 43.8 | Z18: =IF(F18<=Constraints!$B$4,"PASS","FAIL") -> PASS | AA18: =IF(H18="","PASS",IF(H18<=Constraints!$B$6,"PASS","FAIL")) -> PASS | AB18: =IF(I18>=Constraints!$B$7,"PASS","FAIL") -> PASS | AC18: =IF(AND(U18>=Constraints!$B$8,V18=0),"PASS","FAIL") -> PASS | AD18: =IF(Y18>=Constraints!$B$10-0.000001,"PASS","FAIL") -> PASS | AE18: =IF(AND(W18=0,X18=0,G18<=Constraints!$B$5),"PASS","FAIL") -> PASS | AF18: =IF(COUNTIF(Z18:AE18,"FAIL")=0,"PASS","FAIL") -> PASS | AG18: PASS
A19: 16 | B19: dev | C19: seed_015 | D19: hard-busiest | E19: 1 | F19: 529.2 | G19: 663.7 | H19: 36.7 | I19: 1 | J19: 97.6 | K19: 6.7 | L19: 71.3 | M19: 22 | N19: 57.7 | O19: 97.4 | P19: 0.616 | Q19: 4 | R19: 10.75 | S19: 22.8 | T19: 0 | U19: 6 | V19: 0 | W19: 0 | X19: 0 | Y19: 33.2 | Z19: =IF(F19<=Constraints!$B$4,"PASS","FAIL") -> PASS | AA19: =IF(H19="","PASS",IF(H19<=Constraints!$B$6,"PASS","FAIL")) -> PASS | AB19: =IF(I19>=Constraints!$B$7,"PASS","FAIL") -> PASS | AC19: =IF(AND(U19>=Constraints!$B$8,V19=0),"PASS","FAIL") -> PASS | AD19: =IF(Y19>=Constraints!$B$10-0.000001,"PASS","FAIL") -> PASS | AE19: =IF(AND(W19=0,X19=0,G19<=Constraints!$B$5),"PASS","FAIL") -> PASS | AF19: =IF(COUNTIF(Z19:AE19,"FAIL")=0,"PASS","FAIL") -> PASS | AG19: PASS
A20: 17 | B20: dev | C20: seed_016 | D20: failsafe-busiest | E20: 3 | F20: 360.3 | G20: 445.4 | H20: 73.2 | I20: 1 | J20: 95.1 | K20: 13.4 | L20: 46.5 | M20: 40.1 | N20: 75.1 | O20: 96.3 | P20: 0.645 | Q20: 0 | S20: 0 | T20: 0 | U20: 6 | V20: 0 | W20: 0 | X20: 0 | Y20: 35.3 | Z20: =IF(F20<=Constraints!$B$4,"PASS","FAIL") -> PASS | AA20: =IF(H20="","PASS",IF(H20<=Constraints!$B$6,"PASS","FAIL")) -> PASS | AB20: =IF(I20>=Constraints!$B$7,"PASS","FAIL") -> PASS | AC20: =IF(AND(U20>=Constraints!$B$8,V20=0),"PASS","FAIL") -> PASS | AD20: =IF(Y20>=Constraints!$B$10-0.000001,"PASS","FAIL") -> PASS | AE20: =IF(AND(W20=0,X20=0,G20<=Constraints!$B$5),"PASS","FAIL") -> PASS | AF20: =IF(COUNTIF(Z20:AE20,"FAIL")=0,"PASS","FAIL") -> PASS | AG20: PASS
A21: 18 | B21: dev | C21: seed_017 | D21: failsafe-busiest | E21: 3 | F21: 585.9 | G21: 722 | H21: 123.5 | I21: 1 | J21: 98 | K21: 8.6 | L21: 70.9 | M21: 20.5 | N21: 62.1 | O21: 98.1 | P21: 0.619 | Q21: 0 | S21: 0 | T21: 0 | U21: 6 | V21: 0 | W21: 0 | X21: 0 | Y21: 34.2 | Z21: =IF(F21<=Constraints!$B$4,"PASS","FAIL") -> PASS | AA21: =IF(H21="","PASS",IF(H21<=Constraints!$B$6,"PASS","FAIL")) -> PASS | AB21: =IF(I21>=Constraints!$B$7,"PASS","FAIL") -> PASS | AC21: =IF(AND(U21>=Constraints!$B$8,V21=0),"PASS","FAIL") -> PASS | AD21: =IF(Y21>=Constraints!$B$10-0.000001,"PASS","FAIL") -> PASS | AE21: =IF(AND(W21=0,X21=0,G21<=Constraints!$B$5),"PASS","FAIL") -> PASS | AF21: =IF(COUNTIF(Z21:AE21,"FAIL")=0,"PASS","FAIL") -> PASS | AG21: PASS
A22: 19 | B22: dev | C22: seed_018 | D22: hard-busiest | E22: 1 | F22: 622 | G22: 729.7 | H22: 117.5 | I22: 1 | J22: 90.5 | K22: 27.3 | L22: 51.5 | M22: 21.2 | N22: 269.6 | O22: 91.2 | P22: 0.592 | Q22: 4 | R22: 22.14 | S22: 68.4 | T22: 1 | U22: 6 | V22: 0 | W22: 0 | X22: 0 | Y22: 25.4 | Z22: =IF(F22<=Constraints!$B$4,"PASS","FAIL") -> PASS | AA22: =IF(H22="","PASS",IF(H22<=Constraints!$B$6,"PASS","FAIL")) -> PASS | AB22: =IF(I22>=Constraints!$B$7,"PASS","FAIL") -> PASS | AC22: =IF(AND(U22>=Constraints!$B$8,V22=0),"PASS","FAIL") -> PASS | AD22: =IF(Y22>=Constraints!$B$10-0.000001,"PASS","FAIL") -> PASS | AE22: =IF(AND(W22=0,X22=0,G22<=Constraints!$B$5),"PASS","FAIL") -> PASS | AF22: =IF(COUNTIF(Z22:AE22,"FAIL")=0,"PASS","FAIL") -> PASS | AG22: PASS
A23: 20 | B23: dev | C23: seed_019 | D23: failsafe-busiest | E23: 2 | F23: 406.8 | G23: 525.4 | H23: 64.8 | I23: 1 | J23: 95.6 | K23: 17.1 | L23: 48.7 | M23: 34.2 | N23: 82.2 | O23: 96.6 | P23: 0.619 | Q23: 0 | S23: 0 | T23: 0 | U23: 6 | V23: 0 | W23: 0 | X23: 0 | Y23: 42.4 | Z23: =IF(F23<=Constraints!$B$4,"PASS","FAIL") -> PASS | AA23: =IF(H23="","PASS",IF(H23<=Constraints!$B$6,"PASS","FAIL")) -> PASS | AB23: =IF(I23>=Constraints!$B$7,"PASS","FAIL") -> PASS | AC23: =IF(AND(U23>=Constraints!$B$8,V23=0),"PASS","FAIL") -> PASS | AD23: =IF(Y23>=Constraints!$B$10-0.000001,"PASS","FAIL") -> PASS | AE23: =IF(AND(W23=0,X23=0,G23<=Constraints!$B$5),"PASS","FAIL") -> PASS | AF23: =IF(COUNTIF(Z23:AE23,"FAIL")=0,"PASS","FAIL") -> PASS | AG23: PASS
A24: 21 | B24: dev | C24: seed_020 | D24: hard-busiest | E24: 3 | F24: 398.8 | G24: 494.1 | H24: 81.2 | I24: 1 | J24: 92.4 | K24: 30.2 | L24: 21 | M24: 48.8 | N24: 131 | O24: 92.5 | P24: 0.605 | Q24: 0 | S24: 0 | T24: 0 | U24: 6 | V24: 0 | W24: 0 | X24: 0 | Y24: 23.6 | Z24: =IF(F24<=Constraints!$B$4,"PASS","FAIL") -> PASS | AA24: =IF(H24="","PASS",IF(H24<=Constraints!$B$6,"PASS","FAIL")) -> PASS | AB24: =IF(I24>=Constraints!$B$7,"PASS","FAIL") -> PASS | AC24: =IF(AND(U24>=Constraints!$B$8,V24=0),"PASS","FAIL") -> PASS | AD24: =IF(Y24>=Constraints!$B$10-0.000001,"PASS","FAIL") -> PASS | AE24: =IF(AND(W24=0,X24=0,G24<=Constraints!$B$5),"PASS","FAIL") -> PASS | AF24: =IF(COUNTIF(Z24:AE24,"FAIL")=0,"PASS","FAIL") -> PASS | AG24: PASS
A25: 22 | B25: dev | C25: seed_021 | D25: failsafe-busiest | E25: 1 | F25: 410.7 | G25: 530.1 | H25: 54.2 | I25: 1 | J25: 98.2 | K25: 7.4 | L25: 60 | M25: 32.6 | N25: 34.8 | O25: 98.5 | P25: 0.62 | Q25: 0 | S25: 0 | T25: 0 | U25: 6 | V25: 0 | W25: 0 | X25: 0 | Y25: 20.1 | Z25: =IF(F25<=Constraints!$B$4,"PASS","FAIL") -> PASS | AA25: =IF(H25="","PASS",IF(H25<=Constraints!$B$6,"PASS","FAIL")) -> PASS | AB25: =IF(I25>=Constraints!$B$7,"PASS","FAIL") -> PASS | AC25: =IF(AND(U25>=Constraints!$B$8,V25=0),"PASS","FAIL") -> PASS | AD25: =IF(Y25>=Constraints!$B$10-0.000001,"PASS","FAIL") -> PASS | AE25: =IF(AND(W25=0,X25=0,G25<=Constraints!$B$5),"PASS","FAIL") -> PASS | AF25: =IF(COUNTIF(Z25:AE25,"FAIL")=0,"PASS","FAIL") -> PASS | AG25: PASS
A26: 23 | B26: dev | C26: seed_022 | D26: hard-busiest | E26: 1 | F26: 706.8 | G26: 847.9 | H26: 80.9 | I26: 1 | J26: 97.7 | K26: 9.7 | L26: 76.9 | M26: 13.4 | N26: 81.9 | O26: 97.1 | P26: 0.594 | Q26: 0 | S26: 0 | T26: 0 | U26: 6 | V26: 0 | W26: 0 | X26: 0 | Y26: 27.4 | Z26: =IF(F26<=Constraints!$B$4,"PASS","FAIL") -> PASS | AA26: =IF(H26="","PASS",IF(H26<=Constraints!$B$6,"PASS","FAIL")) -> PASS | AB26: =IF(I26>=Constraints!$B$7,"PASS","FAIL") -> PASS | AC26: =IF(AND(U26>=Constraints!$B$8,V26=0),"PASS","FAIL") -> PASS | AD26: =IF(Y26>=Constraints!$B$10-0.000001,"PASS","FAIL") -> PASS | AE26: =IF(AND(W26=0,X26=0,G26<=Constraints!$B$5),"PASS","FAIL") -> PASS | AF26: =IF(COUNTIF(Z26:AE26,"FAIL")=0,"PASS","FAIL") -> PASS | AG26: PASS
A27: 24 | B27: dev | C27: seed_023 | D27: hard-busiest | E27: 1 | F27: 745.9 | G27: 848.4 | H27: 115.7 | I27: 1 | J27: 93.7 | K27: 23 | L27: 57.1 | M27: 20 | N27: 180.8 | O27: 94.3 | P27: 0.596 | Q27: 0 | S27: 0 | T27: 1 | U27: 6 | V27: 0 | W27: 0 | X27: 0 | Y27: 25.3 | Z27: =IF(F27<=Constraints!$B$4,"PASS","FAIL") -> PASS | AA27: =IF(H27="","PASS",IF(H27<=Constraints!$B$6,"PASS","FAIL")) -> PASS | AB27: =IF(I27>=Constraints!$B$7,"PASS","FAIL") -> PASS | AC27: =IF(AND(U27>=Constraints!$B$8,V27=0),"PASS","FAIL") -> PASS | AD27: =IF(Y27>=Constraints!$B$10-0.000001,"PASS","FAIL") -> PASS | AE27: =IF(AND(W27=0,X27=0,G27<=Constraints!$B$5),"PASS","FAIL") -> PASS | AF27: =IF(COUNTIF(Z27:AE27,"FAIL")=0,"PASS","FAIL") -> PASS | AG27: PASS
A28: 25 | B28: dev | C28: seed_024 | D28: failsafe-busiest | E28: 3 | F28: 538.6 | G28: 683.3 | H28: 37.1 | I28: 1 | J28: 92.8 | K28: 21.2 | L28: 62.1 | M28: 16.7 | N28: 201.3 | O28: 93.4 | P28: 0.621 | Q28: 0 | S28: 0 | T28: 0 | U28: 6 | V28: 0 | W28: 0 | X28: 0 | Y28: 30.7 | Z28: =IF(F28<=Constraints!$B$4,"PASS","FAIL") -> PASS | AA28: =IF(H28="","PASS",IF(H28<=Constraints!$B$6,"PASS","FAIL")) -> PASS | AB28: =IF(I28>=Constraints!$B$7,"PASS","FAIL") -> PASS | AC28: =IF(AND(U28>=Constraints!$B$8,V28=0),"PASS","FAIL") -> PASS | AD28: =IF(Y28>=Constraints!$B$10-0.000001,"PASS","FAIL") -> PASS | AE28: =IF(AND(W28=0,X28=0,G28<=Constraints!$B$5),"PASS","FAIL") -> PASS | AF28: =IF(COUNTIF(Z28:AE28,"FAIL")=0,"PASS","FAIL") -> PASS | AG28: PASS
A29: 26 | B29: dev | C29: seed_025 | D29: failsafe-busiest | E29: 2 | F29: 386 | G29: 482.9 | H29: 79.9 | I29: 1 | J29: 91.6 | K29: 30.3 | L29: 35.9 | M29: 33.8 | N29: 141.4 | O29: 93.5 | P29: 0.655 | Q29: 0 | S29: 0 | T29: 0 | U29: 6 | V29: 0 | W29: 0 | X29: 0 | Y29: 35 | Z29: =IF(F29<=Constraints!$B$4,"PASS","FAIL") -> PASS | AA29: =IF(H29="","PASS",IF(H29<=Constraints!$B$6,"PASS","FAIL")) -> PASS | AB29: =IF(I29>=Constraints!$B$7,"PASS","FAIL") -> PASS | AC29: =IF(AND(U29>=Constraints!$B$8,V29=0),"PASS","FAIL") -> PASS | AD29: =IF(Y29>=Constraints!$B$10-0.000001,"PASS","FAIL") -> PASS | AE29: =IF(AND(W29=0,X29=0,G29<=Constraints!$B$5),"PASS","FAIL") -> PASS | AF29: =IF(COUNTIF(Z29:AE29,"FAIL")=0,"PASS","FAIL") -> PASS | AG29: PASS
A30: 27 | B30: dev | C30: seed_026 | D30: hard-busiest | E30: 3 | F30: 467.9 | G30: 565.9 | H30: 85.4 | I30: 1 | J30: 90.9 | K30: 22.6 | L30: 49.6 | M30: 27.8 | N30: 189.6 | O30: 91.9 | P30: 0.625 | Q30: 4 | R30: 30.34 | S30: 100.4 | T30: 0 | U30: 6 | V30: 0 | W30: 0 | X30: 0 | Y30: 33.4 | Z30: =IF(F30<=Constraints!$B$4,"PASS","FAIL") -> PASS | AA30: =IF(H30="","PASS",IF(H30<=Constraints!$B$6,"PASS","FAIL")) -> PASS | AB30: =IF(I30>=Constraints!$B$7,"PASS","FAIL") -> PASS | AC30: =IF(AND(U30>=Constraints!$B$8,V30=0),"PASS","FAIL") -> PASS | AD30: =IF(Y30>=Constraints!$B$10-0.000001,"PASS","FAIL") -> PASS | AE30: =IF(AND(W30=0,X30=0,G30<=Constraints!$B$5),"PASS","FAIL") -> PASS | AF30: =IF(COUNTIF(Z30:AE30,"FAIL")=0,"PASS","FAIL") -> PASS | AG30: PASS
A31: 28 | B31: dev | C31: seed_027 | D31: failsafe-busiest | E31: 1 | F31: 760.3 | G31: 861.8 | H31: 104.7 | I31: 1 | J31: 94.5 | K31: 22.1 | L31: 56.1 | M31: 21.8 | N31: 176.9 | O31: 95.4 | P31: 0.58 | Q31: 0 | S31: 0 | T31: 1 | U31: 6 | V31: 0 | W31: 0 | X31: 0 | Y31: 25.2 | Z31: =IF(F31<=Constraints!$B$4,"PASS","FAIL") -> PASS | AA31: =IF(H31="","PASS",IF(H31<=Constraints!$B$6,"PASS","FAIL")) -> PASS | AB31: =IF(I31>=Constraints!$B$7,"PASS","FAIL") -> PASS | AC31: =IF(AND(U31>=Constraints!$B$8,V31=0),"PASS","FAIL") -> PASS | AD31: =IF(Y31>=Constraints!$B$10-0.000001,"PASS","FAIL") -> PASS | AE31: =IF(AND(W31=0,X31=0,G31<=Constraints!$B$5),"PASS","FAIL") -> PASS | AF31: =IF(COUNTIF(Z31:AE31,"FAIL")=0,"PASS","FAIL") -> PASS | AG31: PASS
A32: 29 | B32: dev | C32: seed_028 | D32: hard-busiest | E32: 1 | F32: 678.3 | G32: 811.9 | H32: 145.6 | I32: 1 | J32: 97.4 | K32: 10.3 | L32: 72.5 | M32: 17.2 | N32: 77.6 | O32: 97.1 | P32: 0.604 | Q32: 0 | S32: 0 | T32: 0 | U32: 6 | V32: 0 | W32: 0 | X32: 0 | Y32: 27.4 | Z32: =IF(F32<=Constraints!$B$4,"PASS","FAIL") -> PASS | AA32: =IF(H32="","PASS",IF(H32<=Constraints!$B$6,"PASS","FAIL")) -> PASS | AB32: =IF(I32>=Constraints!$B$7,"PASS","FAIL") -> PASS | AC32: =IF(AND(U32>=Constraints!$B$8,V32=0),"PASS","FAIL") -> PASS | AD32: =IF(Y32>=Constraints!$B$10-0.000001,"PASS","FAIL") -> PASS | AE32: =IF(AND(W32=0,X32=0,G32<=Constraints!$B$5),"PASS","FAIL") -> PASS | AF32: =IF(COUNTIF(Z32:AE32,"FAIL")=0,"PASS","FAIL") -> PASS | AG32: PASS
A33: 30 | B33: dev | C33: seed_029 | D33: hard-busiest | E33: 4 | F33: 531.9 | G33: 667.3 | H33: 127.9 | I33: 1 | J33: 90.7 | K33: 16.5 | L33: 64.3 | M33: 19.2 | N33: 248.3 | O33: 90.7 | P33: 0.655 | Q33: 4 | R33: 37.06 | S33: 127.7 | T33: 0 | U33: 6.01 | V33: 0 | W33: 0 | X33: 0 | Y33: 31.2 | Z33: =IF(F33<=Constraints!$B$4,"PASS","FAIL") -> PASS | AA33: =IF(H33="","PASS",IF(H33<=Constraints!$B$6,"PASS","FAIL")) -> PASS | AB33: =IF(I33>=Constraints!$B$7,"PASS","FAIL") -> PASS | AC33: =IF(AND(U33>=Constraints!$B$8,V33=0),"PASS","FAIL") -> PASS | AD33: =IF(Y33>=Constraints!$B$10-0.000001,"PASS","FAIL") -> PASS | AE33: =IF(AND(W33=0,X33=0,G33<=Constraints!$B$5),"PASS","FAIL") -> PASS | AF33: =IF(COUNTIF(Z33:AE33,"FAIL")=0,"PASS","FAIL") -> PASS | AG33: PASS
A34: 31 | B34: held-out | C34: seed_100 | D34: failsafe-busiest | E34: 1 | F34: 532.7 | G34: 672.1 | H34: 23.3 | I34: 1 | J34: 97.7 | K34: 9.3 | L34: 68.8 | M34: 22 | N34: 56.7 | O34: 98.1 | P34: 0.606 | Q34: 0 | S34: 0 | T34: 0 | U34: 6 | V34: 0 | W34: 0 | X34: 0 | Y34: 27.9 | Z34: =IF(F34<=Constraints!$B$4,"PASS","FAIL") -> PASS | AA34: =IF(H34="","PASS",IF(H34<=Constraints!$B$6,"PASS","FAIL")) -> PASS | AB34: =IF(I34>=Constraints!$B$7,"PASS","FAIL") -> PASS | AC34: =IF(AND(U34>=Constraints!$B$8,V34=0),"PASS","FAIL") -> PASS | AD34: =IF(Y34>=Constraints!$B$10-0.000001,"PASS","FAIL") -> PASS | AE34: =IF(AND(W34=0,X34=0,G34<=Constraints!$B$5),"PASS","FAIL") -> PASS | AF34: =IF(COUNTIF(Z34:AE34,"FAIL")=0,"PASS","FAIL") -> PASS | AG34: PASS
A35: 32 | B35: held-out | C35: seed_101 | D35: failsafe-busiest | E35: 4 | F35: 699.9 | G35: 844.4 | H35: 108.6 | I35: 1 | J35: 92.4 | K35: 20.8 | L35: 64.8 | M35: 14.4 | N35: 240.3 | O35: 94.1 | P35: 0.617 | Q35: 0 | S35: 0 | T35: 1 | U35: 6 | V35: 0 | W35: 0 | X35: 0 | Y35: 22.5 | Z35: =IF(F35<=Constraints!$B$4,"PASS","FAIL") -> PASS | AA35: =IF(H35="","PASS",IF(H35<=Constraints!$B$6,"PASS","FAIL")) -> PASS | AB35: =IF(I35>=Constraints!$B$7,"PASS","FAIL") -> PASS | AC35: =IF(AND(U35>=Constraints!$B$8,V35=0),"PASS","FAIL") -> PASS | AD35: =IF(Y35>=Constraints!$B$10-0.000001,"PASS","FAIL") -> PASS | AE35: =IF(AND(W35=0,X35=0,G35<=Constraints!$B$5),"PASS","FAIL") -> PASS | AF35: =IF(COUNTIF(Z35:AE35,"FAIL")=0,"PASS","FAIL") -> PASS | AG35: PASS
A36: 33 | B36: held-out | C36: seed_102 | D36: failsafe-busiest | E36: 3 | F36: 508.8 | G36: 652.2 | H36: 178.8 | I36: 1 | J36: 93.1 | K36: 16.6 | L36: 60.9 | M36: 22.6 | N36: 163.6 | O36: 94.7 | P36: 0.642 | Q36: 0 | S36: 0 | T36: 0 | U36: 6 | V36: 0 | W36: 0 | X36: 0 | Y36: 27.6 | Z36: =IF(F36<=Constraints!$B$4,"PASS","FAIL") -> PASS | AA36: =IF(H36="","PASS",IF(H36<=Constraints!$B$6,"PASS","FAIL")) -> PASS | AB36: =IF(I36>=Constraints!$B$7,"PASS","FAIL") -> PASS | AC36: =IF(AND(U36>=Constraints!$B$8,V36=0),"PASS","FAIL") -> PASS | AD36: =IF(Y36>=Constraints!$B$10-0.000001,"PASS","FAIL") -> PASS | AE36: =IF(AND(W36=0,X36=0,G36<=Constraints!$B$5),"PASS","FAIL") -> PASS | AF36: =IF(COUNTIF(Z36:AE36,"FAIL")=0,"PASS","FAIL") -> PASS | AG36: PASS
A37: 34 | B37: held-out | C37: seed_103 | D37: failsafe-busiest | E37: 4 | F37: 566.8 | G37: 668.7 | H37: 98.4 | I37: 1 | J37: 97 | K37: 11.5 | L37: 62.9 | M37: 25.6 | N37: 76.5 | O37: 97.5 | P37: 0.609 | Q37: 0 | S37: 0 | T37: 1 | U37: 6.3 | V37: 0 | W37: 0 | X37: 0 | Y37: 21.9 | Z37: =IF(F37<=Constraints!$B$4,"PASS","FAIL") -> PASS | AA37: =IF(H37="","PASS",IF(H37<=Constraints!$B$6,"PASS","FAIL")) -> PASS | AB37: =IF(I37>=Constraints!$B$7,"PASS","FAIL") -> PASS | AC37: =IF(AND(U37>=Constraints!$B$8,V37=0),"PASS","FAIL") -> PASS | AD37: =IF(Y37>=Constraints!$B$10-0.000001,"PASS","FAIL") -> PASS | AE37: =IF(AND(W37=0,X37=0,G37<=Constraints!$B$5),"PASS","FAIL") -> PASS | AF37: =IF(COUNTIF(Z37:AE37,"FAIL")=0,"PASS","FAIL") -> PASS | AG37: PASS
A38: 35 | B38: held-out | C38: seed_104 | D38: failsafe-busiest | E38: 1 | F38: 468.5 | G38: 606 | H38: 88.8 | I38: 1 | J38: 97 | K38: 11.9 | L38: 59.4 | M38: 28.7 | N38: 65.1 | O38: 97.5 | P38: 0.587 | Q38: 0 | S38: 0 | T38: 0 | U38: 6 | V38: 0 | W38: 0 | X38: 0 | Y38: 37.1 | Z38: =IF(F38<=Constraints!$B$4,"PASS","FAIL") -> PASS | AA38: =IF(H38="","PASS",IF(H38<=Constraints!$B$6,"PASS","FAIL")) -> PASS | AB38: =IF(I38>=Constraints!$B$7,"PASS","FAIL") -> PASS | AC38: =IF(AND(U38>=Constraints!$B$8,V38=0),"PASS","FAIL") -> PASS | AD38: =IF(Y38>=Constraints!$B$10-0.000001,"PASS","FAIL") -> PASS | AE38: =IF(AND(W38=0,X38=0,G38<=Constraints!$B$5),"PASS","FAIL") -> PASS | AF38: =IF(COUNTIF(Z38:AE38,"FAIL")=0,"PASS","FAIL") -> PASS | AG38: PASS
A39: 36 | B39: held-out | C39: seed_105 | D39: failsafe-busiest | E39: 1 | F39: 624.3 | G39: 750.9 | H39: 112.1 | I39: 1 | J39: 93.3 | K39: 21.5 | L39: 55.8 | M39: 22.7 | N39: 185.2 | O39: 94.3 | P39: 0.586 | Q39: 0 | S39: 0 | T39: 1 | U39: 6 | V39: 0 | W39: 0 | X39: 0 | Y39: 24 | Z39: =IF(F39<=Constraints!$B$4,"PASS","FAIL") -> PASS | AA39: =IF(H39="","PASS",IF(H39<=Constraints!$B$6,"PASS","FAIL")) -> PASS | AB39: =IF(I39>=Constraints!$B$7,"PASS","FAIL") -> PASS | AC39: =IF(AND(U39>=Constraints!$B$8,V39=0),"PASS","FAIL") -> PASS | AD39: =IF(Y39>=Constraints!$B$10-0.000001,"PASS","FAIL") -> PASS | AE39: =IF(AND(W39=0,X39=0,G39<=Constraints!$B$5),"PASS","FAIL") -> PASS | AF39: =IF(COUNTIF(Z39:AE39,"FAIL")=0,"PASS","FAIL") -> PASS | AG39: PASS
A40: 37 | B40: held-out | C40: seed_106 | D40: hard-busiest | E40: 3 | F40: 776.1 | G40: 884.6 | H40: 217.7 | I40: 0.875 | J40: 93.1 | K40: 22.3 | L40: 62.1 | M40: 15.7 | N40: 229.6 | O40: 93.5 | P40: 0.589 | Q40: 3 | R40: 20.74 | S40: 46.3 | T40: 1 | U40: 6 | V40: 0 | W40: 0 | X40: 0 | Y40: 24.1 | Z40: =IF(F40<=Constraints!$B$4,"PASS","FAIL") -> PASS | AA40: =IF(H40="","PASS",IF(H40<=Constraints!$B$6,"PASS","FAIL")) -> PASS | AB40: =IF(I40>=Constraints!$B$7,"PASS","FAIL") -> PASS | AC40: =IF(AND(U40>=Constraints!$B$8,V40=0),"PASS","FAIL") -> PASS | AD40: =IF(Y40>=Constraints!$B$10-0.000001,"PASS","FAIL") -> PASS | AE40: =IF(AND(W40=0,X40=0,G40<=Constraints!$B$5),"PASS","FAIL") -> PASS | AF40: =IF(COUNTIF(Z40:AE40,"FAIL")=0,"PASS","FAIL") -> PASS | AG40: PASS
...

Sheet Planner Comparison
A1: Same 60 scenarios, four planners (values from results/evaluation/*.json; median / worst)
A3: Metric | B3: Set | C3: adaptive-spare | D3: adaptive-reserve | E3: adaptive-conditional | F3: fixed-baseline
A4: Operational success (runs of 30) | B4: dev | C4: 30 | D4: 30 | E4: 28 | F4: 4
A5: Eventually complete (runs of 30) | B5: dev | C5: 30 | D5: 30 | E5: 30 | F5: 22
A6: Imagery complete, median (s) | B6: dev | C6: 514.1 | D6: 619.9 | E6: 560.3 | F6: 738.7
A7: Imagery complete, worst (s) | B7: dev | C7: 760.3 | D7: 824.6 | E7: 1066 | F7: 2263.3
A8: High-priority response, worst (s) | B8: dev | C8: 145.6 | D8: 128.1 | E8: 142.9 | F8: 1899.8
A9: Connectivity, median (%) | B9: dev | C9: 94 | D9: 91.8 | E9: 93.4 | F9: 43.4
A10: Connectivity, worst (%) | B10: dev | C10: 90 | D10: 85.9 | E10: 79.7 | F10: 19.9
A11: UAVs orphaned by fault, mean | B11: dev | C11: 1.2 | D11: 0 | E11: 0.5 | F11: 1.1
A12: Stable recovery confirmed, median (s) | B12: dev | C12: 22.14 | D12: none orphaned | E12: 19.01 | F12: 52.1
A13: Near misses (total events) | B13: dev | C13: 0 | D13: 0 | E13: 0 | F13: 0
A14: Collisions (total events) | B14: dev | C14: 0 | D14: 0 | E14: 0 | F14: 0
A16: Operational success (runs of 30) | B16: held-out | C16: 30 | D16: 27 | E16: 30 | F16: 4
A17: Eventually complete (runs of 30) | B17: held-out | C17: 30 | D17: 30 | E17: 30 | F17: 27
A18: Imagery complete, median (s) | B18: held-out | C18: 589.9 | D18: 640.7 | E18: 645.6 | F18: 828
A19: Imagery complete, worst (s) | B19: held-out | C19: 871.5 | D19: 907.9 | E19: 891 | F19: 2356.3
A20: High-priority response, worst (s) | B20: held-out | C20: 217.7 | D20: 287.7 | E20: 227.8 | F20: 757.7
A21: Connectivity, median (%) | B21: held-out | C21: 93.1 | D21: 91.8 | E21: 92.6 | F21: 44.6
A22: Connectivity, worst (%) | B22: held-out | C22: 74.9 | D22: 85.6 | E22: 76.2 | F22: 17.2
A23: UAVs orphaned by fault, mean | B23: held-out | C23: 0.9 | D23: 0 | E23: 0.2 | F23: 0.7
A24: Stable recovery confirmed, median (s) | B24: held-out | C24: 20.8 | D24: none orphaned | E24: 6.46 | F24: 66.43
A25: Near misses (total events) | B25: held-out | C25: 0 | D25: 0 | E25: 0 | F25: 0
A26: Collisions (total events) | B26: held-out | C26: 0 | D26: 0 | E26: 0 | F26: 0
A28: Hardcoded values: copied from the benchmark summaries written by tools/evaluate.py (results/evaluation/E1-busiest__dev.json, __heldout.json).

Sheet Notes
A1: How these results were produced
A2: Command: python tools/evaluate.py (saved scenarios in scenarios/dev and scenarios/heldout).
A3: Each scenario: 7 random sites 0.5-2.4 km from the GCS, random initial batteries (45-100 %),
A4: a critical fault (hard or failsafe) on the busiest relay at 100-260 s, a new high-priority site,
A5: a 15-60 s radio outage and a 35-55 % energy-availability fault on the GCS-side relay.
A6: Channel loss uses common random numbers, so every planner sees the same channel realisation.
A8: Definitions (full list in docs/METRICS.md and in the PDF report)
A9: Connectivity % = mean over time of (airborne UAVs with a route / airborne UAVs).
A10: Disconnected UAV-s = sum over 64 ms steps of (airborne UAVs without a route) x 0.064 s.
A11: Heartbeat PDR % = heartbeats delivered within 2 s / heartbeats generated (per send cohort).
A12: Stable recovery confirmed = start of the first 5 s interval with every orphaned UAV routed, + 5 s.
A13: Min separation = closest approach of any UAV pair, checked continuously between samples.
... A16: flight, abstracted faults, uncalibrated radio model, time-compressed 60 s battery swap.
